Workbook

Sheet ReadMe
B2: WORKERS ACCOMMODATION VILLAGE — RESOURCE AND OPERATING PLAN
B3: 300-person peak · 38-month programme · multi-company site
B4: ETABLIX — Integrated Site Services, part of Groupe Nseya
B7: WHAT THIS IS | C7: A working model, not a picture of one. Change a driver on Assumptions and every bed, cover, litre, kilowatt, bus seat, FTE and pound downstream moves with it. Nothing below Assumptions is typed in by hand.
B9: HOW TO USE IT | C9: 1. Set the drivers on Assumptions. Blue cells are yours to change; yellow are the ones that move the answer most.
C10: 2. Put your real companies, teams and dates on Teams. Add or delete rows — everything else follows the range.
C11: 3. Read Workforce, then BedDemand. Those two decide the village.
C12: 4. Accommodation, Facilities, Utilities, Transport and VillageStaff size what you build and who runs it.
C13: 5. Capex, Opex and CostSummary cost it. Replace every rate with your own quotation before anyone quotes from this.
C14: 6. Compliance, Risks and Mobilisation are the parts that get forgotten and then hurt.
B16: COLOUR | C16: Blue text = type here. Black = calculated, do not overtype. Green = pulled from another sheet. Yellow fill = a driver that changes the answer materially.
B18: THE ONE RULE | C18: Every figure here is a first-pass planning figure for validation by a competent person. It is not a design, a price or an instruction. Loads, flows, ratios and durations size a decision; they do not survive procurement without an engineer, and nothing safety-critical is resolved in a spreadsheet.
B20: ON THE COSTS | C20: Every rate on Capex and Opex is INDICATIVE and marked as such — an order-of-magnitude figure to size the decision, not a quotation and not a budget. They are blue because they are yours to replace. A number taken from here into a tender without a supplier behind it is your risk, not an estimate.
B22: WHAT DRIVES WHAT
B24: Teams → Workforce | C24: each team's start, peak and end become a headcount curve across 38 months
B25: Workforce → BedDemand | C25: travelling percentage per team turns headcount into people needing a bed
B26: BedDemand → Accommodation | C26: peak beds, plus void, contingency and accessible provision, becomes a room schedule
B27: BedDemand → Facilities | C27: occupancy becomes canteen covers, laundry machines, drying, WCs and social space
B28: BedDemand → Utilities | C28: occupancy becomes water, foul, power, heat and waste, month by month
B29: BedDemand → Transport | C29: residents become bus seats, journeys and parking
B30: BedDemand → VillageStaff | C30: occupancy becomes the FTEs who run the village, 24/7 cover included
B31: Accommodation → Capex | C31: rooms and blocks become what it costs to create the village
B32: VillageStaff + Utilities → Opex | C32: people, energy and consumption become what it costs to run it each month
B33: Capex + Opex → CostSummary | C33: whole-life cost, cost per bed-night, and the cost recharged to each company
B34: Packages → Capex | C34: the five packages you buy — civil works, modular accommodation, kitchen, furniture, FM and operation
B35: Packages → the interfaces | C35: fifteen of them. A village fails between packages, not inside them — that table is the one to argue about before anything is let
B36: Capex + Opex → CostSummary | C36: whole-life cost by package, cost per bed-night, and the break-even against booking rooms

Sheet Assumptions
B2: ASSUMPTIONS AND DRIVERS
B3: Blue = type here. Yellow = changes the answer materially. Every figure carries its basis; a basis of “to verify” means exactly that.
A5: ONE PLACE FOR EVERY NUMBER THIS PLAN RESTS ON
B6: Driver | C6: Value | D6: Unit | E6: Basis — and whether it is verified
A8: PROJECT
B9: Project / site | C9: Project NORTHREACH — worked example | E9: Replace with the real project. Nothing else keys off this.
B10: Programme start (month 1) | C10: 46388 | D10: date | E10: A real date, not text. Every month label across the workbook is EDATE from this cell, so a text value here puts #VALUE! in 190 header cells.
B11: Programme duration | C11: 38 | D11: months | E11: The plan is built for 38 columns. Changing this does not add columns.
B12: Peak site population | C12: =MAX(Workforce!C29:AN29) | D12: people | E12: Calculated from Teams. The headline 300 is the planning figure; the model says what the curve actually peaks at.
B13: Peak travelling population | C13: =MAX(BedDemand!C7:AN7) | D13: people | E13: The number that decides the village. Everyone else goes home at night.
A15: WHO NEEDS A BED
B16: Rooms allocated per traveller | C16: 1 | D16: rooms | E16: One room per person. Sharing on rotation cuts rooms but needs strict rota discipline and personal storage; drop to 0.7 only if the rotation is contractual.
B17: Rotation presence factor | C17: 1 | D17: × | E17: 1.00 = everyone on site at once. A 3-on/1-off rotation is about 0.75. Verify against the actual rota before sizing.
B18: Void and turnover allowance | C18: 0.05 | D18: % | E18: Rooms out of service for cleaning, changeover, damage and maintenance. Industry practice 4–6%; to verify against your operator.
B19: Contingency rooms | C19: 0.05 | D19: % | E19: Headroom for a package running late over one running early. Not a substitute for a proper curve.
B20: Female provision | C20: 0.08 | D20: % | E20: Of the travelling population. Drives a separate lockable block or floor, not just a room count. Set from your own diversity data — 8% is a placeholder.
B21: Accessible rooms | C21: 0.05 | D21: % | E21: Wheelchair-accessible rooms with level access and accessible WC/shower. Confirm the required proportion with Building Control — this is a placeholder, not a standard.
B22: Senior / manager rooms | C22: 0.06 | D22: % | E22: Larger room with a desk. A commercial decision, not a requirement.
B23: Visitor and spare rooms | C23: 6 | D23: rooms | E23: Auditors, inspectors, client visits, isolation. Not optional in practice.
A25: ROOM AND BLOCK SIZING
B26: Standard room — floor area | C26: 11 | D26: m² | E26: Single ensuite. Typical modular workforce room 10–12 m² including shower room. To verify against the module you actually procure.
B27: Accessible room — floor area | C27: 16 | D27: m² | E27: Turning circle and accessible shower room. To verify with Building Control.
B28: Senior room — floor area | C28: 14 | D28: m²
B29: Rooms per accommodation block | C29: 24 | D29: rooms | E29: Two storeys of twelve is a common modular block. Set from the supplier's standard module.
B30: Circulation, plant and stair gross-up | C30: 1.35 | D30: × | E30: Corridors, stairs, risers, plant. Applied to net room area to get gross block area.
B31: External space per bed | C31: 45 | D31: m² | E31: Roads, parking, footpaths, drainage, landscaping and the standoff between blocks for fire and privacy. At 22 m² the total site came out at 0.75 ha for 225 rooms, which cannot hold roads, parking and separation. 45 m² gives about 1.6 ha, which is the order a village of this size actually occupies. To verify against a real layout.
A33: CATERING
B34: Take breakfast on site | C34: 0.85 | D34: % | E34: Of residents. Drives covers and food cost.
B35: Take evening meal on site | C35: 0.92 | D35: % | E35: Of residents.
B36: Packed lunches taken | C36: 0.9 | D36: % | E36: Of residents. Made in the same kitchen, no covers needed.
B37: Sittings per meal service | C37: 2 | D37: no. | E37: Two sittings halves the dining room. Three is possible and unpopular.
B38: Dining area per cover | C38: 1.6 | D38: m² | E38: Table, chair and circulation. 1.5–1.8 m² typical; to verify.
B39: Kitchen and servery per cover | C39: 0.55 | D39: m² | E39: Preparation, cooking, servery, wash-up, dry and cold store. To verify with the caterer.
A41: LAUNDRY, HOUSEKEEPING AND SOCIAL
B42: Residents per washing machine | C42: 14 | D42: people | E42: Self-service laundry. To verify — depends whether linen is contracted out.
B43: Residents per tumble dryer | C43: 16 | D43: people
B44: Drying room capacity per 100 residents | C44: 1 | D44: rooms | E44: Wet PPE and boots. Separate from the laundry and non-negotiable in a wet climate.
B45: Rooms cleaned per housekeeper per shift | C45: 18 | D45: rooms | E45: Full clean and linen change. To verify with the operator.
B46: Linen change frequency | C46: 1 | D46: per week
B47: Gym area per 100 residents | C47: 45 | D47: m² | E47: A gym is not a luxury on a 38-month village; it is retention.
...

Sheet Teams
A2: COMPANIES AND TEAMS
A3: Every blue cell is yours. Add or remove rows inside the block and the whole model follows — but if you add rows below the last team, extend the ranges on Workforce and BedDemand to match.
A4: Ref | B4: Company | C4: Team / package | D4: Trade | E4: Peak | F4: Start month | G4: At full month | H4: Last full month | I4: End month | J4: Travelling % | K4: Shift pattern | L4: Role | M4: Notes
A5: T01 | B5: Marrowbridge Infrastructure Ltd | C5: Project management team | D5: Management | E5: 18 | F5: 1 | G5: 3 | H5: 36 | I5: 38 | J5: 0.55 | K5: Days Mon–Fri | L5: Main contractor
A6: T02 | B6: Marrowbridge Infrastructure Ltd | C6: Site supervision | D6: Supervision | E6: 20 | F6: 3 | G6: 6 | H6: 34 | I6: 36 | J6: 0.6 | K6: Days + back shift | L6: Main contractor
A7: T03 | B7: Marrowbridge Infrastructure Ltd | C7: HSEQ & quality | D7: HSEQ | E7: 8 | F7: 2 | G7: 4 | H7: 35 | I7: 37 | J7: 0.5 | K7: Days Mon–Fri | L7: Main contractor
A8: T04 | B8: Redmoor Groundworks Ltd | C8: Earthworks gang A | D8: Earthworks | E8: 34 | F8: 3 | G8: 5 | H8: 14 | I8: 16 | J8: 0.35 | K8: Days 6/7 | L8: Subcontractor
A9: T05 | B9: Redmoor Groundworks Ltd | C9: Earthworks gang B | D9: Earthworks | E9: 26 | F9: 5 | G9: 7 | H9: 13 | I9: 15 | J9: 0.35 | K9: Days 6/7 | L9: Subcontractor
A10: T06 | B10: Calderbrook Civils Ltd | C10: Compound & hardstanding | D10: Civils | E10: 30 | F10: 2 | G10: 4 | H10: 9 | I10: 11 | J10: 0.4 | K10: Days 6/7 | L10: Subcontractor
A11: T07 | B11: Calderbrook Civils Ltd | C11: Foundations & structures | D11: Civils | E11: 33 | F11: 8 | G11: 11 | H11: 22 | I11: 25 | J11: 0.45 | K11: Days 6/7 | L11: Subcontractor
A12: T08 | B12: Calderbrook Civils Ltd | C12: Drainage & ducting | D12: Civils | E12: 16 | F12: 6 | G12: 8 | H12: 20 | I12: 22 | J12: 0.4 | K12: Days 6/7 | L12: Subcontractor
A13: T09 | B13: Northgate Steel Ltd | C13: Steel erection | D13: Steelwork | E13: 33 | F13: 14 | G13: 17 | H13: 26 | I13: 29 | J13: 0.8 | K13: Two shift | L13: Subcontractor
A14: T10 | B14: Northgate Steel Ltd | C14: Cladding & envelope | D14: Envelope | E14: 21 | F14: 20 | G14: 22 | H14: 30 | I14: 32 | J14: 0.75 | K14: Two shift | L14: Subcontractor
A15: T11 | B15: Ledwyn Scaffolding Ltd | C15: Scaffold gangs | D15: Scaffold | E15: 14 | F15: 12 | G15: 14 | H15: 30 | I15: 33 | J15: 0.7 | K15: Days 6/7 | L15: Subcontractor
A16: T12 | B16: Penmark Cable Services Ltd | C16: Cable pulling | D16: Cable | E16: 26 | F16: 16 | G16: 19 | H16: 30 | I16: 33 | J16: 0.85 | K16: Two shift | L16: Specialist
... A26: T22 | B26: Hollins Catering Ltd | C26: Catering & housekeeping | D26: Catering | E26: 14 | F26: 2 | G26: 4 | H26: 37 | I26: 38 | J26: 0.4 | K26: Split shift | L26: Village operator
B28: Companies represented | E28: =SUMPRODUCT(1/COUNTIF(B5:B26,B5:B26))
B29: Teams | E29: =COUNTA(A5:A26)
B30: Sum of team peaks (not the site peak — teams peak at different times) | E30: =SUM(E5:E26)

Sheet Packages
B2: THE FIVE PACKAGES — AND WHAT FALLS BETWEEN THEM
B3: Five packages is a clean way to buy a village. It also creates fifteen interfaces, and a village fails at the interfaces, not inside the packages. The second table is the one to argue about before anything is let.
B5: Ref | C5: Package | D5: In one line | E5: What is in it | F5: What is expressly NOT in it
B6: P1 | C6: Civil works | D6: Everything below and between the buildings | E6: Site clearance, cut and fill, ground improvement · foundations, bases and plinths for every module · roads, hardstanding, footpaths, parking · surface and foul drainage · incoming utility infrastructure to the module connection point · fencing, gates, lighting columns · landscaping · reinstatement at the end | F6: Above the module connection point · anything inside a module · maintenance of roads and drainage once the village is live
B7: P2 | C7: Modular accommodation | D7: The buildings, delivered and connected | E7: Bedroom blocks · amenity buildings (gym, social, laundry, drying) · reception and village office · corridors, stairs, fire compartmentation · module transport, craneage and setting out · internal M&E within the module · connection to the civils' termination points · commissioning of the building services | F7: Ground preparation and bases · loose furniture · catering equipment · operation
B8: P3 | C8: Kitchen | D8: The catering facility as a working kitchen | E8: Kitchen fit-out, servery and wash-up · cold and dry stores · extraction, interlocks and gas safety · catering equipment supply and commissioning · food hygiene registration support · dining room servery counters | F8: The building shell (P2) · dining tables and chairs (P4) · the people who cook (P5)
B9: P4 | C9: Furniture | D9: Everything loose, in every room | E9: Bed, mattress, wardrobe, desk, chair, storage per bedroom · soft furnishings, curtains, floor coverings if loose · dining tables and chairs · social and gym furniture · office and reception furniture · white goods in laundries · signage | F9: Fixed joinery inside modules (P2) · catering equipment (P3) · replacement of damaged items in operation (P5)
B10: P5 | C10: FM and operation | D10: Running it for 38 months | E10: Village management, reception 24/7, security 24/7 · housekeeping and linen · catering operation and food supply · maintenance, grounds and waste · transport and drivers · utilities management and metering · resident welfare, inductions and complaints · statutory compliance in operation — legionella, fire, gas, electrical, food hygiene | F10: Capital replacement · anything that is a defect under P1–P4
A13: THE INTERFACES — WHERE THE MONEY AND THE ARGUMENTS ARE
B14: Ref | C14: Between | D14: The interface | E14: What fails if nobody owns it | F14: Where it should sit
B15: IF-01 | C15: P1 ↔ P2 | D15: Setting-out, levels and base tolerance for every module | E15: Modules arrive to bases that are out of tolerance. Craneage stands, the programme slips a week per block, and neither party accepts the levels. | F15: P1 sets out and certifies levels to the module supplier's tolerance, in writing, before delivery.
B16: IF-02 | C16: P1 ↔ P2 | D16: The utility termination point — exactly where civils stop and the module starts | E16: Water, foul, power and comms arrive near the module but not connected to it. Two contractors each price to the other's boundary and neither crosses it. | F16: One drawing showing a termination point per service per block, signed by both. This is the commonest village dispute there is.
B17: IF-03 | C17: P2 ↔ P3 | D17: Whether the kitchen is a module or a fit-out into a shell | E17: The kitchen is ordered twice or not at all. Extraction penetrations are not in the module drawing and get cut on site. | F17: Decide before P2 is ordered. If a fit-out, P2 supplies a shell with agreed penetrations, floor loading and drainage falls.
B18: IF-04 | C18: P3 ↔ P4 | D18: Dining tables and chairs | E18: The dining room has a servery and no seats on opening day. Both packages assumed the other had it. | F18: P4. Anything loose is furniture, including in the dining room — say so in both scopes.
B19: IF-05 | C19: P2 ↔ P4 | D19: Fixed joinery versus loose furniture in the bedroom | E19: Wardrobes and desks are either duplicated or missing. Modular suppliers vary on what is included as standard. | F19: Fix the bedroom specification item by item before either package is let, and attach it to both.
B20: IF-06 | C20: P4 ↔ P5 | D20: Replacement of damaged or worn furniture over 38 months | E20: Broken beds are nobody's, and rooms go out of service. Void rate rises and nobody can say why. | F20: P5, from a replacement allowance funded in Opex, with a stock level agreed at handover.
B21: IF-07 | C21: P1 ↔ P5 | D21: Maintenance of roads, drainage, lighting and grounds in operation | E21: Gullies block, the car park floods, the access degrades under bus traffic and there is no maintenance budget. | F21: P5, with a condition survey at handover defining the standard being taken on.
B22: IF-08 | C22: P3 ↔ P5 | D22: Ownership and maintenance of catering equipment, and who holds the hygiene registration | E22: Equipment fails, warranty is disputed, and the registration is in the wrong name at the first inspection. | F22: P5 holds the registration and the maintenance; P3 hands over with warranties assigned and an asset register.
B23: IF-09 | C23: P2 ↔ P5 | D23: Building services commissioning, handover and the defects period | E23: The village is occupied before commissioning is complete, and defects become operational problems nobody logs. | F23: No occupation before commissioning sign-off. A defects liaison route in P5's scope from day one.
B24: IF-10 | C24: P2 ↔ P5 | D24: Legionella duty from first fill of the water system | E24: The system is filled at installation and sits at low occupancy for weeks. The duty starts at fill; nobody has started flushing. | F24: P5 takes the water safety plan from first fill, not from first occupation. Write it into P2's handover.
B25: IF-11 | C25: P1 ↔ P3 | D25: Kitchen drainage, grease interceptor and its maintenance | E25: The interceptor is installed by one and never emptied by anyone. | F25: P1 installs to P3's specification; P5 maintains it on a stated frequency.
... B29: IF-15 | C29: All five ↔ the project | D29: One accountable owner for the village as a system | E29: Five suppliers each doing their scope correctly while nobody owns whether the village works. This is precisely the gap ETABLIX exists to close. | F29: A single integrator over all five, with the interface register above as their instrument.

Sheet Workforce
A2: WORKFORCE CURVE — HEADCOUNT BY TEAM, BY MONTH
A3: Calculated from Teams. Nothing here is typed. A team ramps from its start month to full, holds, then ramps down to its end month.
B5: Month label | C5: =TEXT(EDATE(Assumptions!$C$10,0),"mmm-yy") | D5: =TEXT(EDATE(Assumptions!$C$10,1),"mmm-yy") | E5: =TEXT(EDATE(Assumptions!$C$10,2),"mmm-yy") | F5: =TEXT(EDATE(Assumptions!$C$10,3),"mmm-yy") | G5: =TEXT(EDATE(Assumptions!$C$10,4),"mmm-yy") | H5: =TEXT(EDATE(Assumptions!$C$10,5),"mmm-yy") | I5: =TEXT(EDATE(Assumptions!$C$10,6),"mmm-yy") | J5: =TEXT(EDATE(Assumptions!$C$10,7),"mmm-yy") | K5: =TEXT(EDATE(Assumptions!$C$10,8),"mmm-yy") | L5: =TEXT(EDATE(Assumptions!$C$10,9),"mmm-yy") | M5: =TEXT(EDATE(Assumptions!$C$10,10),"mmm-yy") | N5: =TEXT(EDATE(Assumptions!$C$10,11),"mmm-yy") | O5: =TEXT(EDATE(Assumptions!$C$10,12),"mmm-yy") | P5: =TEXT(EDATE(Assumptions!$C$10,13),"mmm-yy") | Q5: =TEXT(EDATE(Assumptions!$C$10,14),"mmm-yy") | R5: =TEXT(EDATE(Assumptions!$C$10,15),"mmm-yy") | S5: =TEXT(EDATE(Assumptions!$C$10,16),"mmm-yy") | T5: =TEXT(EDATE(Assumptions!$C$10,17),"mmm-yy") | U5: =TEXT(EDATE(Assumptions!$C$10,18),"mmm-yy") | V5: =TEXT(EDATE(Assumptions!$C$10,19),"mmm-yy") | W5: =TEXT(EDATE(Assumptions!$C$10,20),"mmm-yy") | X5: =TEXT(EDATE(Assumptions!$C$10,21),"mmm-yy") | Y5: =TEXT(EDATE(Assumptions!$C$10,22),"mmm-yy") | Z5: =TEXT(EDATE(Assumptions!$C$10,23),"mmm-yy") | AA5: =TEXT(EDATE(Assumptions!$C$10,24),"mmm-yy") | AB5: =TEXT(EDATE(Assumptions!$C$10,25),"mmm-yy") | AC5: =TEXT(EDATE(Assumptions!$C$10,26),"mmm-yy") | AD5: =TEXT(EDATE(Assumptions!$C$10,27),"mmm-yy") | AE5: =TEXT(EDATE(Assumptions!$C$10,28),"mmm-yy") | AF5: =TEXT(EDATE(Assumptions!$C$10,29),"mmm-yy") | AG5: =TEXT(EDATE(Assumptions!$C$10,30),"mmm-yy") | AH5: =TEXT(EDATE(Assumptions!$C$10,31),"mmm-yy") | AI5: =TEXT(EDATE(Assumptions!$C$10,32),"mmm-yy") | AJ5: =TEXT(EDATE(Assumptions!$C$10,33),"mmm-yy") | AK5: =TEXT(EDATE(Assumptions!$C$10,34),"mmm-yy") | AL5: =TEXT(EDATE(Assumptions!$C$10,35),"mmm-yy") | AM5: =TEXT(EDATE(Assumptions!$C$10,36),"mmm-yy") | AN5: =TEXT(EDATE(Assumptions!$C$10,37),"mmm-yy")
B6: Month number | C6: 1 | D6: 2 | E6: 3 | F6: 4 | G6: 5 | H6: 6 | I6: 7 | J6: 8 | K6: 9 | L6: 10 | M6: 11 | N6: 12 | O6: 13 | P6: 14 | Q6: 15 | R6: 16 | S6: 17 | T6: 18 | U6: 19 | V6: 20 | W6: 21 | X6: 22 | Y6: 23 | Z6: 24 | AA6: 25 | AB6: 26 | AC6: 27 | AD6: 28 | AE6: 29 | AF6: 30 | AG6: 31 | AH6: 32 | AI6: 33 | AJ6: 34 | AK6: 35 | AL6: 36 | AM6: 37 | AN6: 38
A7: =Teams!A5 | B7: =Teams!C5&" — "&Teams!B5 | C7: =IF(OR(C$6<Teams!$F5,C$6>Teams!$I5),0,IF(C$6<Teams!$G5,ROUND(Teams!$E5*(C$6-Teams!$F5+1)/(Teams!$G5-Teams!$F5+1),0),IF(C$6<=Teams!$H5,Teams!$E5,ROUND(Teams!$E5*(Teams!$I5-C$6+1)/(Teams!$I5-Teams!$H5),0)))) | D7: =IF(OR(D$6<Teams!$F5,D$6>Teams!$I5),0,IF(D$6<Teams!$G5,ROUND(Teams!$E5*(D$6-Teams!$F5+1)/(Teams!$G5-Teams!$F5+1),0),IF(D$6<=Teams!$H5,Teams!$E5,ROUND(Teams!$E5*(Teams!$I5-D$6+1)/(Teams!$I5-Teams!$H5),0)))) | E7: =IF(OR(E$6<Teams!$F5,E$6>Teams!$I5),0,IF(E$6<Teams!$G5,ROUND(Teams!$E5*(E$6-Teams!$F5+1)/(Teams!$G5-Teams!$F5+1),0),IF(E$6<=Teams!$H5,Teams!$E5,ROUND(Teams!$E5*(Teams!$I5-E$6+1)/(Teams!$I5-Teams!$H5),0)))) | F7: =IF(OR(F$6<Teams!$F5,F$6>Teams!$I5),0,IF(F$6<Teams!$G5,ROUND(Teams!$E5*(F$6-Teams!$F5+1)/(Teams!$G5-Teams!$F5+1),0),IF(F$6<=Teams!$H5,Teams!$E5,ROUND(Teams!$E5*(Teams!$I5-F$6+1)/(Teams!$I5-Teams!$H5),0)))) | G7: =IF(OR(G$6<Teams!$F5,G$6>Teams!$I5),0,IF(G$6<Teams!$G5,ROUND(Teams!$E5*(G$6-Teams!$F5+1)/(Teams!$G5-Teams!$F5+1),0),IF(G$6<=Teams!$H5,Teams!$E5,ROUND(Teams!$E5*(Teams!$I5-G$6+1)/(Teams!$I5-Teams!$H5),0)))) | H7: =IF(OR(H$6<Teams!$F5,H$6>Teams!$I5),0,IF(H$6<Teams!$G5,ROUND(Teams!$E5*(H$6-Teams!$F5+1)/(Teams!$G5-Teams!$F5+1),0),IF(H$6<=Teams!$H5,Teams!$E5,ROUND(Teams!$E5*(Teams!$I5-H$6+1)/(Teams!$I5-Teams!$H5),0)))) | I7: =IF(OR(I$6<Teams!$F5,I$6>Teams!$I5),0,IF(I$6<Teams!$G5,ROUND(Teams!$E5*(I$6-Teams!$F5+1)/(Teams!$G5-Teams!$F5+1),0),IF(I$6<=Teams!$H5,Teams!$E5,ROUND(Teams!$E5*(Teams!$I5-I$6+1)/(Teams!$I5-Teams!$H5),0)))) | J7: =IF(OR(J$6<Teams!$F5,J$6>Teams!$I5),0,IF(J$6<Teams!$G5,ROUND(Teams!$E5*(J$6-Teams!$F5+1)/(Teams!$G5-Teams!$F5+1),0),IF(J$6<=Teams!$H5,Teams!$E5,ROUND(Teams!$E5*(Teams!$I5-J$6+1)/(Teams!$I5-Teams!$H5),0)))) | ... AN7: =IF(OR(AN$6<Teams!$F5,AN$6>Teams!$I5),0,IF(AN$6<Teams!$G5,ROUND(Teams!$E5*(AN$6-Teams!$F5+1)/(Teams!$G5-Teams!$F5+1),0),IF(AN$6<=Teams!$H5,Teams!$E5,ROUND(Teams!$E5*(Teams!$I5-AN$6+1)/(Teams!$I5-Teams!$H5),0))))
A8: =Teams!A6 | B8: =Teams!C6&" — "&Teams!B6 | C8: =IF(OR(C$6<Teams!$F6,C$6>Teams!$I6),0,IF(C$6<Teams!$G6,ROUND(Teams!$E6*(C$6-Teams!$F6+1)/(Teams!$G6-Teams!$F6+1),0),IF(C$6<=Teams!$H6,Teams!$E6,ROUND(Teams!$E6*(Teams!$I6-C$6+1)/(Teams!$I6-Teams!$H6),0)))) | D8: =IF(OR(D$6<Teams!$F6,D$6>Teams!$I6),0,IF(D$6<Teams!$G6,ROUND(Teams!$E6*(D$6-Teams!$F6+1)/(Teams!$G6-Teams!$F6+1),0),IF(D$6<=Teams!$H6,Teams!$E6,ROUND(Teams!$E6*(Teams!$I6-D$6+1)/(Teams!$I6-Teams!$H6),0)))) | E8: =IF(OR(E$6<Teams!$F6,E$6>Teams!$I6),0,IF(E$6<Teams!$G6,ROUND(Teams!$E6*(E$6-Teams!$F6+1)/(Teams!$G6-Teams!$F6+1),0),IF(E$6<=Teams!$H6,Teams!$E6,ROUND(Teams!$E6*(Teams!$I6-E$6+1)/(Teams!$I6-Teams!$H6),0)))) | F8: =IF(OR(F$6<Teams!$F6,F$6>Teams!$I6),0,IF(F$6<Teams!$G6,ROUND(Teams!$E6*(F$6-Teams!$F6+1)/(Teams!$G6-Teams!$F6+1),0),IF(F$6<=Teams!$H6,Teams!$E6,ROUND(Teams!$E6*(Teams!$I6-F$6+1)/(Teams!$I6-Teams!$H6),0)))) | G8: =IF(OR(G$6<Teams!$F6,G$6>Teams!$I6),0,IF(G$6<Teams!$G6,ROUND(Teams!$E6*(G$6-Teams!$F6+1)/(Teams!$G6-Teams!$F6+1),0),IF(G$6<=Teams!$H6,Teams!$E6,ROUND(Teams!$E6*(Teams!$I6-G$6+1)/(Teams!$I6-Teams!$H6),0)))) | H8: =IF(OR(H$6<Teams!$F6,H$6>Teams!$I6),0,IF(H$6<Teams!$G6,ROUND(Teams!$E6*(H$6-Teams!$F6+1)/(Teams!$G6-Teams!$F6+1),0),IF(H$6<=Teams!$H6,Teams!$E6,ROUND(Teams!$E6*(Teams!$I6-H$6+1)/(Teams!$I6-Teams!$H6),0)))) | I8: =IF(OR(I$6<Teams!$F6,I$6>Teams!$I6),0,IF(I$6<Teams!$G6,ROUND(Teams!$E6*(I$6-Teams!$F6+1)/(Teams!$G6-Teams!$F6+1),0),IF(I$6<=Teams!$H6,Teams!$E6,ROUND(Teams!$E6*(Teams!$I6-I$6+1)/(Teams!$I6-Teams!$H6),0)))) | J8: =IF(OR(J$6<Teams!$F6,J$6>Teams!$I6),0,IF(J$6<Teams!$G6,ROUND(Teams!$E6*(J$6-Teams!$F6+1)/(Teams!$G6-Teams!$F6+1),0),IF(J$6<=Teams!$H6,Teams!$E6,ROUND(Teams!$E6*(Teams!$I6-J$6+1)/(Teams!$I6-Teams!$H6),0)))) | ... AN8: =IF(OR(AN$6<Teams!$F6,AN$6>Teams!$I6),0,IF(AN$6<Teams!$G6,ROUND(Teams!$E6*(AN$6-Teams!$F6+1)/(Teams!$G6-Teams!$F6+1),0),IF(AN$6<=Teams!$H6,Teams!$E6,ROUND(Teams!$E6*(Teams!$I6-AN$6+1)/(Teams!$I6-Teams!$H6),0))))
A9: =Teams!A7 | B9: =Teams!C7&" — "&Teams!B7 | C9: =IF(OR(C$6<Teams!$F7,C$6>Teams!$I7),0,IF(C$6<Teams!$G7,ROUND(Teams!$E7*(C$6-Teams!$F7+1)/(Teams!$G7-Teams!$F7+1),0),IF(C$6<=Teams!$H7,Teams!$E7,ROUND(Teams!$E7*(Teams!$I7-C$6+1)/(Teams!$I7-Teams!$H7),0)))) | D9: =IF(OR(D$6<Teams!$F7,D$6>Teams!$I7),0,IF(D$6<Teams!$G7,ROUND(Teams!$E7*(D$6-Teams!$F7+1)/(Teams!$G7-Teams!$F7+1),0),IF(D$6<=Teams!$H7,Teams!$E7,ROUND(Teams!$E7*(Teams!$I7-D$6+1)/(Teams!$I7-Teams!$H7),0)))) | E9: =IF(OR(E$6<Teams!$F7,E$6>Teams!$I7),0,IF(E$6<Teams!$G7,ROUND(Teams!$E7*(E$6-Teams!$F7+1)/(Teams!$G7-Teams!$F7+1),0),IF(E$6<=Teams!$H7,Teams!$E7,ROUND(Teams!$E7*(Teams!$I7-E$6+1)/(Teams!$I7-Teams!$H7),0)))) | F9: =IF(OR(F$6<Teams!$F7,F$6>Teams!$I7),0,IF(F$6<Teams!$G7,ROUND(Teams!$E7*(F$6-Teams!$F7+1)/(Teams!$G7-Teams!$F7+1),0),IF(F$6<=Teams!$H7,Teams!$E7,ROUND(Teams!$E7*(Teams!$I7-F$6+1)/(Teams!$I7-Teams!$H7),0)))) | G9: =IF(OR(G$6<Teams!$F7,G$6>Teams!$I7),0,IF(G$6<Teams!$G7,ROUND(Teams!$E7*(G$6-Teams!$F7+1)/(Teams!$G7-Teams!$F7+1),0),IF(G$6<=Teams!$H7,Teams!$E7,ROUND(Teams!$E7*(Teams!$I7-G$6+1)/(Teams!$I7-Teams!$H7),0)))) | H9: =IF(OR(H$6<Teams!$F7,H$6>Teams!$I7),0,IF(H$6<Teams!$G7,ROUND(Teams!$E7*(H$6-Teams!$F7+1)/(Teams!$G7-Teams!$F7+1),0),IF(H$6<=Teams!$H7,Teams!$E7,ROUND(Teams!$E7*(Teams!$I7-H$6+1)/(Teams!$I7-Teams!$H7),0)))) | I9: =IF(OR(I$6<Teams!$F7,I$6>Teams!$I7),0,IF(I$6<Teams!$G7,ROUND(Teams!$E7*(I$6-Teams!$F7+1)/(Teams!$G7-Teams!$F7+1),0),IF(I$6<=Teams!$H7,Teams!$E7,ROUND(Teams!$E7*(Teams!$I7-I$6+1)/(Teams!$I7-Teams!$H7),0)))) | J9: =IF(OR(J$6<Teams!$F7,J$6>Teams!$I7),0,IF(J$6<Teams!$G7,ROUND(Teams!$E7*(J$6-Teams!$F7+1)/(Teams!$G7-Teams!$F7+1),0),IF(J$6<=Teams!$H7,Teams!$E7,ROUND(Teams!$E7*(Teams!$I7-J$6+1)/(Teams!$I7-Teams!$H7),0)))) | ... AN9: =IF(OR(AN$6<Teams!$F7,AN$6>Teams!$I7),0,IF(AN$6<Teams!$G7,ROUND(Teams!$E7*(AN$6-Teams!$F7+1)/(Teams!$G7-Teams!$F7+1),0),IF(AN$6<=Teams!$H7,Teams!$E7,ROUND(Teams!$E7*(Teams!$I7-AN$6+1)/(Teams!$I7-Teams!$H7),0))))
A10: =Teams!A8 | B10: =Teams!C8&" — "&Teams!B8 | C10: =IF(OR(C$6<Teams!$F8,C$6>Teams!$I8),0,IF(C$6<Teams!$G8,ROUND(Teams!$E8*(C$6-Teams!$F8+1)/(Teams!$G8-Teams!$F8+1),0),IF(C$6<=Teams!$H8,Teams!$E8,ROUND(Teams!$E8*(Teams!$I8-C$6+1)/(Teams!$I8-Teams!$H8),0)))) | D10: =IF(OR(D$6<Teams!$F8,D$6>Teams!$I8),0,IF(D$6<Teams!$G8,ROUND(Teams!$E8*(D$6-Teams!$F8+1)/(Teams!$G8-Teams!$F8+1),0),IF(D$6<=Teams!$H8,Teams!$E8,ROUND(Teams!$E8*(Teams!$I8-D$6+1)/(Teams!$I8-Teams!$H8),0)))) | E10: =IF(OR(E$6<Teams!$F8,E$6>Teams!$I8),0,IF(E$6<Teams!$G8,ROUND(Teams!$E8*(E$6-Teams!$F8+1)/(Teams!$G8-Teams!$F8+1),0),IF(E$6<=Teams!$H8,Teams!$E8,ROUND(Teams!$E8*(Teams!$I8-E$6+1)/(Teams!$I8-Teams!$H8),0)))) | F10: =IF(OR(F$6<Teams!$F8,F$6>Teams!$I8),0,IF(F$6<Teams!$G8,ROUND(Teams!$E8*(F$6-Teams!$F8+1)/(Teams!$G8-Teams!$F8+1),0),IF(F$6<=Teams!$H8,Teams!$E8,ROUND(Teams!$E8*(Teams!$I8-F$6+1)/(Teams!$I8-Teams!$H8),0)))) | G10: =IF(OR(G$6<Teams!$F8,G$6>Teams!$I8),0,IF(G$6<Teams!$G8,ROUND(Teams!$E8*(G$6-Teams!$F8+1)/(Teams!$G8-Teams!$F8+1),0),IF(G$6<=Teams!$H8,Teams!$E8,ROUND(Teams!$E8*(Teams!$I8-G$6+1)/(Teams!$I8-Teams!$H8),0)))) | H10: =IF(OR(H$6<Teams!$F8,H$6>Teams!$I8),0,IF(H$6<Teams!$G8,ROUND(Teams!$E8*(H$6-Teams!$F8+1)/(Teams!$G8-Teams!$F8+1),0),IF(H$6<=Teams!$H8,Teams!$E8,ROUND(Teams!$E8*(Teams!$I8-H$6+1)/(Teams!$I8-Teams!$H8),0)))) | I10: =IF(OR(I$6<Teams!$F8,I$6>Teams!$I8),0,IF(I$6<Teams!$G8,ROUND(Teams!$E8*(I$6-Teams!$F8+1)/(Teams!$G8-Teams!$F8+1),0),IF(I$6<=Teams!$H8,Teams!$E8,ROUND(Teams!$E8*(Teams!$I8-I$6+1)/(Teams!$I8-Teams!$H8),0)))) | J10: =IF(OR(J$6<Teams!$F8,J$6>Teams!$I8),0,IF(J$6<Teams!$G8,ROUND(Teams!$E8*(J$6-Teams!$F8+1)/(Teams!$G8-Teams!$F8+1),0),IF(J$6<=Teams!$H8,Teams!$E8,ROUND(Teams!$E8*(Teams!$I8-J$6+1)/(Teams!$I8-Teams!$H8),0)))) | ... AN10: =IF(OR(AN$6<Teams!$F8,AN$6>Teams!$I8),0,IF(AN$6<Teams!$G8,ROUND(Teams!$E8*(AN$6-Teams!$F8+1)/(Teams!$G8-Teams!$F8+1),0),IF(AN$6<=Teams!$H8,Teams!$E8,ROUND(Teams!$E8*(Teams!$I8-AN$6+1)/(Teams!$I8-Teams!$H8),0))))
A11: =Teams!A9 | B11: =Teams!C9&" — "&Teams!B9 | C11: =IF(OR(C$6<Teams!$F9,C$6>Teams!$I9),0,IF(C$6<Teams!$G9,ROUND(Teams!$E9*(C$6-Teams!$F9+1)/(Teams!$G9-Teams!$F9+1),0),IF(C$6<=Teams!$H9,Teams!$E9,ROUND(Teams!$E9*(Teams!$I9-C$6+1)/(Teams!$I9-Teams!$H9),0)))) | D11: =IF(OR(D$6<Teams!$F9,D$6>Teams!$I9),0,IF(D$6<Teams!$G9,ROUND(Teams!$E9*(D$6-Teams!$F9+1)/(Teams!$G9-Teams!$F9+1),0),IF(D$6<=Teams!$H9,Teams!$E9,ROUND(Teams!$E9*(Teams!$I9-D$6+1)/(Teams!$I9-Teams!$H9),0)))) | E11: =IF(OR(E$6<Teams!$F9,E$6>Teams!$I9),0,IF(E$6<Teams!$G9,ROUND(Teams!$E9*(E$6-Teams!$F9+1)/(Teams!$G9-Teams!$F9+1),0),IF(E$6<=Teams!$H9,Teams!$E9,ROUND(Teams!$E9*(Teams!$I9-E$6+1)/(Teams!$I9-Teams!$H9),0)))) | F11: =IF(OR(F$6<Teams!$F9,F$6>Teams!$I9),0,IF(F$6<Teams!$G9,ROUND(Teams!$E9*(F$6-Teams!$F9+1)/(Teams!$G9-Teams!$F9+1),0),IF(F$6<=Teams!$H9,Teams!$E9,ROUND(Teams!$E9*(Teams!$I9-F$6+1)/(Teams!$I9-Teams!$H9),0)))) | G11: =IF(OR(G$6<Teams!$F9,G$6>Teams!$I9),0,IF(G$6<Teams!$G9,ROUND(Teams!$E9*(G$6-Teams!$F9+1)/(Teams!$G9-Teams!$F9+1),0),IF(G$6<=Teams!$H9,Teams!$E9,ROUND(Teams!$E9*(Teams!$I9-G$6+1)/(Teams!$I9-Teams!$H9),0)))) | H11: =IF(OR(H$6<Teams!$F9,H$6>Teams!$I9),0,IF(H$6<Teams!$G9,ROUND(Teams!$E9*(H$6-Teams!$F9+1)/(Teams!$G9-Teams!$F9+1),0),IF(H$6<=Teams!$H9,Teams!$E9,ROUND(Teams!$E9*(Teams!$I9-H$6+1)/(Teams!$I9-Teams!$H9),0)))) | I11: =IF(OR(I$6<Teams!$F9,I$6>Teams!$I9),0,IF(I$6<Teams!$G9,ROUND(Teams!$E9*(I$6-Teams!$F9+1)/(Teams!$G9-Teams!$F9+1),0),IF(I$6<=Teams!$H9,Teams!$E9,ROUND(Teams!$E9*(Teams!$I9-I$6+1)/(Teams!$I9-Teams!$H9),0)))) | J11: =IF(OR(J$6<Teams!$F9,J$6>Teams!$I9),0,IF(J$6<Teams!$G9,ROUND(Teams!$E9*(J$6-Teams!$F9+1)/(Teams!$G9-Teams!$F9+1),0),IF(J$6<=Teams!$H9,Teams!$E9,ROUND(Teams!$E9*(Teams!$I9-J$6+1)/(Teams!$I9-Teams!$H9),0)))) | ... AN11: =IF(OR(AN$6<Teams!$F9,AN$6>Teams!$I9),0,IF(AN$6<Teams!$G9,ROUND(Teams!$E9*(AN$6-Teams!$F9+1)/(Teams!$G9-Teams!$F9+1),0),IF(AN$6<=Teams!$H9,Teams!$E9,ROUND(Teams!$E9*(Teams!$I9-AN$6+1)/(Teams!$I9-Teams!$H9),0))))
A12: =Teams!A10 | B12: =Teams!C10&" — "&Teams!B10 | C12: =IF(OR(C$6<Teams!$F10,C$6>Teams!$I10),0,IF(C$6<Teams!$G10,ROUND(Teams!$E10*(C$6-Teams!$F10+1)/(Teams!$G10-Teams!$F10+1),0),IF(C$6<=Teams!$H10,Teams!$E10,ROUND(Teams!$E10*(Teams!$I10-C$6+1)/(Teams!$I10-Teams!$H10),0)))) | D12: =IF(OR(D$6<Teams!$F10,D$6>Teams!$I10),0,IF(D$6<Teams!$G10,ROUND(Teams!$E10*(D$6-Teams!$F10+1)/(Teams!$G10-Teams!$F10+1),0),IF(D$6<=Teams!$H10,Teams!$E10,ROUND(Teams!$E10*(Teams!$I10-D$6+1)/(Teams!$I10-Teams!$H10),0)))) | E12: =IF(OR(E$6<Teams!$F10,E$6>Teams!$I10),0,IF(E$6<Teams!$G10,ROUND(Teams!$E10*(E$6-Teams!$F10+1)/(Teams!$G10-Teams!$F10+1),0),IF(E$6<=Teams!$H10,Teams!$E10,ROUND(Teams!$E10*(Teams!$I10-E$6+1)/(Teams!$I10-Teams!$H10),0)))) | F12: =IF(OR(F$6<Teams!$F10,F$6>Teams!$I10),0,IF(F$6<Teams!$G10,ROUND(Teams!$E10*(F$6-Teams!$F10+1)/(Teams!$G10-Teams!$F10+1),0),IF(F$6<=Teams!$H10,Teams!$E10,ROUND(Teams!$E10*(Teams!$I10-F$6+1)/(Teams!$I10-Teams!$H10),0)))) | G12: =IF(OR(G$6<Teams!$F10,G$6>Teams!$I10),0,IF(G$6<Teams!$G10,ROUND(Teams!$E10*(G$6-Teams!$F10+1)/(Teams!$G10-Teams!$F10+1),0),IF(G$6<=Teams!$H10,Teams!$E10,ROUND(Teams!$E10*(Teams!$I10-G$6+1)/(Teams!$I10-Teams!$H10),0)))) | H12: =IF(OR(H$6<Teams!$F10,H$6>Teams!$I10),0,IF(H$6<Teams!$G10,ROUND(Teams!$E10*(H$6-Teams!$F10+1)/(Teams!$G10-Teams!$F10+1),0),IF(H$6<=Teams!$H10,Teams!$E10,ROUND(Teams!$E10*(Teams!$I10-H$6+1)/(Teams!$I10-Teams!$H10),0)))) | I12: =IF(OR(I$6<Teams!$F10,I$6>Teams!$I10),0,IF(I$6<Teams!$G10,ROUND(Teams!$E10*(I$6-Teams!$F10+1)/(Teams!$G10-Teams!$F10+1),0),IF(I$6<=Teams!$H10,Teams!$E10,ROUND(Teams!$E10*(Teams!$I10-I$6+1)/(Teams!$I10-Teams!$H10),0)))) | J12: =IF(OR(J$6<Teams!$F10,J$6>Teams!$I10),0,IF(J$6<Teams!$G10,ROUND(Teams!$E10*(J$6-Teams!$F10+1)/(Teams!$G10-Teams!$F10+1),0),IF(J$6<=Teams!$H10,Teams!$E10,ROUND(Teams!$E10*(Teams!$I10-J$6+1)/(Teams!$I10-Teams!$H10),0)))) | ... AN12: =IF(OR(AN$6<Teams!$F10,AN$6>Teams!$I10),0,IF(AN$6<Teams!$G10,ROUND(Teams!$E10*(AN$6-Teams!$F10+1)/(Teams!$G10-Teams!$F10+1),0),IF(AN$6<=Teams!$H10,Teams!$E10,ROUND(Teams!$E10*(Teams!$I10-AN$6+1)/(Teams!$I10-Teams!$H10),0))))
A13: =Teams!A11 | B13: =Teams!C11&" — "&Teams!B11 | C13: =IF(OR(C$6<Teams!$F11,C$6>Teams!$I11),0,IF(C$6<Teams!$G11,ROUND(Teams!$E11*(C$6-Teams!$F11+1)/(Teams!$G11-Teams!$F11+1),0),IF(C$6<=Teams!$H11,Teams!$E11,ROUND(Teams!$E11*(Teams!$I11-C$6+1)/(Teams!$I11-Teams!$H11),0)))) | D13: =IF(OR(D$6<Teams!$F11,D$6>Teams!$I11),0,IF(D$6<Teams!$G11,ROUND(Teams!$E11*(D$6-Teams!$F11+1)/(Teams!$G11-Teams!$F11+1),0),IF(D$6<=Teams!$H11,Teams!$E11,ROUND(Teams!$E11*(Teams!$I11-D$6+1)/(Teams!$I11-Teams!$H11),0)))) | E13: =IF(OR(E$6<Teams!$F11,E$6>Teams!$I11),0,IF(E$6<Teams!$G11,ROUND(Teams!$E11*(E$6-Teams!$F11+1)/(Teams!$G11-Teams!$F11+1),0),IF(E$6<=Teams!$H11,Teams!$E11,ROUND(Teams!$E11*(Teams!$I11-E$6+1)/(Teams!$I11-Teams!$H11),0)))) | F13: =IF(OR(F$6<Teams!$F11,F$6>Teams!$I11),0,IF(F$6<Teams!$G11,ROUND(Teams!$E11*(F$6-Teams!$F11+1)/(Teams!$G11-Teams!$F11+1),0),IF(F$6<=Teams!$H11,Teams!$E11,ROUND(Teams!$E11*(Teams!$I11-F$6+1)/(Teams!$I11-Teams!$H11),0)))) | G13: =IF(OR(G$6<Teams!$F11,G$6>Teams!$I11),0,IF(G$6<Teams!$G11,ROUND(Teams!$E11*(G$6-Teams!$F11+1)/(Teams!$G11-Teams!$F11+1),0),IF(G$6<=Teams!$H11,Teams!$E11,ROUND(Teams!$E11*(Teams!$I11-G$6+1)/(Teams!$I11-Teams!$H11),0)))) | H13: =IF(OR(H$6<Teams!$F11,H$6>Teams!$I11),0,IF(H$6<Teams!$G11,ROUND(Teams!$E11*(H$6-Teams!$F11+1)/(Teams!$G11-Teams!$F11+1),0),IF(H$6<=Teams!$H11,Teams!$E11,ROUND(Teams!$E11*(Teams!$I11-H$6+1)/(Teams!$I11-Teams!$H11),0)))) | I13: =IF(OR(I$6<Teams!$F11,I$6>Teams!$I11),0,IF(I$6<Teams!$G11,ROUND(Teams!$E11*(I$6-Teams!$F11+1)/(Teams!$G11-Teams!$F11+1),0),IF(I$6<=Teams!$H11,Teams!$E11,ROUND(Teams!$E11*(Teams!$I11-I$6+1)/(Teams!$I11-Teams!$H11),0)))) | J13: =IF(OR(J$6<Teams!$F11,J$6>Teams!$I11),0,IF(J$6<Teams!$G11,ROUND(Teams!$E11*(J$6-Teams!$F11+1)/(Teams!$G11-Teams!$F11+1),0),IF(J$6<=Teams!$H11,Teams!$E11,ROUND(Teams!$E11*(Teams!$I11-J$6+1)/(Teams!$I11-Teams!$H11),0)))) | ... AN13: =IF(OR(AN$6<Teams!$F11,AN$6>Teams!$I11),0,IF(AN$6<Teams!$G11,ROUND(Teams!$E11*(AN$6-Teams!$F11+1)/(Teams!$G11-Teams!$F11+1),0),IF(AN$6<=Teams!$H11,Teams!$E11,ROUND(Teams!$E11*(Teams!$I11-AN$6+1)/(Teams!$I11-Teams!$H11),0))))
A14: =Teams!A12 | B14: =Teams!C12&" — "&Teams!B12 | C14: =IF(OR(C$6<Teams!$F12,C$6>Teams!$I12),0,IF(C$6<Teams!$G12,ROUND(Teams!$E12*(C$6-Teams!$F12+1)/(Teams!$G12-Teams!$F12+1),0),IF(C$6<=Teams!$H12,Teams!$E12,ROUND(Teams!$E12*(Teams!$I12-C$6+1)/(Teams!$I12-Teams!$H12),0)))) | D14: =IF(OR(D$6<Teams!$F12,D$6>Teams!$I12),0,IF(D$6<Teams!$G12,ROUND(Teams!$E12*(D$6-Teams!$F12+1)/(Teams!$G12-Teams!$F12+1),0),IF(D$6<=Teams!$H12,Teams!$E12,ROUND(Teams!$E12*(Teams!$I12-D$6+1)/(Teams!$I12-Teams!$H12),0)))) | E14: =IF(OR(E$6<Teams!$F12,E$6>Teams!$I12),0,IF(E$6<Teams!$G12,ROUND(Teams!$E12*(E$6-Teams!$F12+1)/(Teams!$G12-Teams!$F12+1),0),IF(E$6<=Teams!$H12,Teams!$E12,ROUND(Teams!$E12*(Teams!$I12-E$6+1)/(Teams!$I12-Teams!$H12),0)))) | F14: =IF(OR(F$6<Teams!$F12,F$6>Teams!$I12),0,IF(F$6<Teams!$G12,ROUND(Teams!$E12*(F$6-Teams!$F12+1)/(Teams!$G12-Teams!$F12+1),0),IF(F$6<=Teams!$H12,Teams!$E12,ROUND(Teams!$E12*(Teams!$I12-F$6+1)/(Teams!$I12-Teams!$H12),0)))) | G14: =IF(OR(G$6<Teams!$F12,G$6>Teams!$I12),0,IF(G$6<Teams!$G12,ROUND(Teams!$E12*(G$6-Teams!$F12+1)/(Teams!$G12-Teams!$F12+1),0),IF(G$6<=Teams!$H12,Teams!$E12,ROUND(Teams!$E12*(Teams!$I12-G$6+1)/(Teams!$I12-Teams!$H12),0)))) | H14: =IF(OR(H$6<Teams!$F12,H$6>Teams!$I12),0,IF(H$6<Teams!$G12,ROUND(Teams!$E12*(H$6-Teams!$F12+1)/(Teams!$G12-Teams!$F12+1),0),IF(H$6<=Teams!$H12,Teams!$E12,ROUND(Teams!$E12*(Teams!$I12-H$6+1)/(Teams!$I12-Teams!$H12),0)))) | I14: =IF(OR(I$6<Teams!$F12,I$6>Teams!$I12),0,IF(I$6<Teams!$G12,ROUND(Teams!$E12*(I$6-Teams!$F12+1)/(Teams!$G12-Teams!$F12+1),0),IF(I$6<=Teams!$H12,Teams!$E12,ROUND(Teams!$E12*(Teams!$I12-I$6+1)/(Teams!$I12-Teams!$H12),0)))) | J14: =IF(OR(J$6<Teams!$F12,J$6>Teams!$I12),0,IF(J$6<Teams!$G12,ROUND(Teams!$E12*(J$6-Teams!$F12+1)/(Teams!$G12-Teams!$F12+1),0),IF(J$6<=Teams!$H12,Teams!$E12,ROUND(Teams!$E12*(Teams!$I12-J$6+1)/(Teams!$I12-Teams!$H12),0)))) | ... AN14: =IF(OR(AN$6<Teams!$F12,AN$6>Teams!$I12),0,IF(AN$6<Teams!$G12,ROUND(Teams!$E12*(AN$6-Teams!$F12+1)/(Teams!$G12-Teams!$F12+1),0),IF(AN$6<=Teams!$H12,Teams!$E12,ROUND(Teams!$E12*(Teams!$I12-AN$6+1)/(Teams!$I12-Teams!$H12),0))))
A15: =Teams!A13 | B15: =Teams!C13&" — "&Teams!B13 | C15: =IF(OR(C$6<Teams!$F13,C$6>Teams!$I13),0,IF(C$6<Teams!$G13,ROUND(Teams!$E13*(C$6-Teams!$F13+1)/(Teams!$G13-Teams!$F13+1),0),IF(C$6<=Teams!$H13,Teams!$E13,ROUND(Teams!$E13*(Teams!$I13-C$6+1)/(Teams!$I13-Teams!$H13),0)))) | D15: =IF(OR(D$6<Teams!$F13,D$6>Teams!$I13),0,IF(D$6<Teams!$G13,ROUND(Teams!$E13*(D$6-Teams!$F13+1)/(Teams!$G13-Teams!$F13+1),0),IF(D$6<=Teams!$H13,Teams!$E13,ROUND(Teams!$E13*(Teams!$I13-D$6+1)/(Teams!$I13-Teams!$H13),0)))) | E15: =IF(OR(E$6<Teams!$F13,E$6>Teams!$I13),0,IF(E$6<Teams!$G13,ROUND(Teams!$E13*(E$6-Teams!$F13+1)/(Teams!$G13-Teams!$F13+1),0),IF(E$6<=Teams!$H13,Teams!$E13,ROUND(Teams!$E13*(Teams!$I13-E$6+1)/(Teams!$I13-Teams!$H13),0)))) | F15: =IF(OR(F$6<Teams!$F13,F$6>Teams!$I13),0,IF(F$6<Teams!$G13,ROUND(Teams!$E13*(F$6-Teams!$F13+1)/(Teams!$G13-Teams!$F13+1),0),IF(F$6<=Teams!$H13,Teams!$E13,ROUND(Teams!$E13*(Teams!$I13-F$6+1)/(Teams!$I13-Teams!$H13),0)))) | G15: =IF(OR(G$6<Teams!$F13,G$6>Teams!$I13),0,IF(G$6<Teams!$G13,ROUND(Teams!$E13*(G$6-Teams!$F13+1)/(Teams!$G13-Teams!$F13+1),0),IF(G$6<=Teams!$H13,Teams!$E13,ROUND(Teams!$E13*(Teams!$I13-G$6+1)/(Teams!$I13-Teams!$H13),0)))) | H15: =IF(OR(H$6<Teams!$F13,H$6>Teams!$I13),0,IF(H$6<Teams!$G13,ROUND(Teams!$E13*(H$6-Teams!$F13+1)/(Teams!$G13-Teams!$F13+1),0),IF(H$6<=Teams!$H13,Teams!$E13,ROUND(Teams!$E13*(Teams!$I13-H$6+1)/(Teams!$I13-Teams!$H13),0)))) | I15: =IF(OR(I$6<Teams!$F13,I$6>Teams!$I13),0,IF(I$6<Teams!$G13,ROUND(Teams!$E13*(I$6-Teams!$F13+1)/(Teams!$G13-Teams!$F13+1),0),IF(I$6<=Teams!$H13,Teams!$E13,ROUND(Teams!$E13*(Teams!$I13-I$6+1)/(Teams!$I13-Teams!$H13),0)))) | J15: =IF(OR(J$6<Teams!$F13,J$6>Teams!$I13),0,IF(J$6<Teams!$G13,ROUND(Teams!$E13*(J$6-Teams!$F13+1)/(Teams!$G13-Teams!$F13+1),0),IF(J$6<=Teams!$H13,Teams!$E13,ROUND(Teams!$E13*(Teams!$I13-J$6+1)/(Teams!$I13-Teams!$H13),0)))) | ... AN15: =IF(OR(AN$6<Teams!$F13,AN$6>Teams!$I13),0,IF(AN$6<Teams!$G13,ROUND(Teams!$E13*(AN$6-Teams!$F13+1)/(Teams!$G13-Teams!$F13+1),0),IF(AN$6<=Teams!$H13,Teams!$E13,ROUND(Teams!$E13*(Teams!$I13-AN$6+1)/(Teams!$I13-Teams!$H13),0))))
A16: =Teams!A14 | B16: =Teams!C14&" — "&Teams!B14 | C16: =IF(OR(C$6<Teams!$F14,C$6>Teams!$I14),0,IF(C$6<Teams!$G14,ROUND(Teams!$E14*(C$6-Teams!$F14+1)/(Teams!$G14-Teams!$F14+1),0),IF(C$6<=Teams!$H14,Teams!$E14,ROUND(Teams!$E14*(Teams!$I14-C$6+1)/(Teams!$I14-Teams!$H14),0)))) | D16: =IF(OR(D$6<Teams!$F14,D$6>Teams!$I14),0,IF(D$6<Teams!$G14,ROUND(Teams!$E14*(D$6-Teams!$F14+1)/(Teams!$G14-Teams!$F14+1),0),IF(D$6<=Teams!$H14,Teams!$E14,ROUND(Teams!$E14*(Teams!$I14-D$6+1)/(Teams!$I14-Teams!$H14),0)))) | E16: =IF(OR(E$6<Teams!$F14,E$6>Teams!$I14),0,IF(E$6<Teams!$G14,ROUND(Teams!$E14*(E$6-Teams!$F14+1)/(Teams!$G14-Teams!$F14+1),0),IF(E$6<=Teams!$H14,Teams!$E14,ROUND(Teams!$E14*(Teams!$I14-E$6+1)/(Teams!$I14-Teams!$H14),0)))) | F16: =IF(OR(F$6<Teams!$F14,F$6>Teams!$I14),0,IF(F$6<Teams!$G14,ROUND(Teams!$E14*(F$6-Teams!$F14+1)/(Teams!$G14-Teams!$F14+1),0),IF(F$6<=Teams!$H14,Teams!$E14,ROUND(Teams!$E14*(Teams!$I14-F$6+1)/(Teams!$I14-Teams!$H14),0)))) | G16: =IF(OR(G$6<Teams!$F14,G$6>Teams!$I14),0,IF(G$6<Teams!$G14,ROUND(Teams!$E14*(G$6-Teams!$F14+1)/(Teams!$G14-Teams!$F14+1),0),IF(G$6<=Teams!$H14,Teams!$E14,ROUND(Teams!$E14*(Teams!$I14-G$6+1)/(Teams!$I14-Teams!$H14),0)))) | H16: =IF(OR(H$6<Teams!$F14,H$6>Teams!$I14),0,IF(H$6<Teams!$G14,ROUND(Teams!$E14*(H$6-Teams!$F14+1)/(Teams!$G14-Teams!$F14+1),0),IF(H$6<=Teams!$H14,Teams!$E14,ROUND(Teams!$E14*(Teams!$I14-H$6+1)/(Teams!$I14-Teams!$H14),0)))) | I16: =IF(OR(I$6<Teams!$F14,I$6>Teams!$I14),0,IF(I$6<Teams!$G14,ROUND(Teams!$E14*(I$6-Teams!$F14+1)/(Teams!$G14-Teams!$F14+1),0),IF(I$6<=Teams!$H14,Teams!$E14,ROUND(Teams!$E14*(Teams!$I14-I$6+1)/(Teams!$I14-Teams!$H14),0)))) | J16: =IF(OR(J$6<Teams!$F14,J$6>Teams!$I14),0,IF(J$6<Teams!$G14,ROUND(Teams!$E14*(J$6-Teams!$F14+1)/(Teams!$G14-Teams!$F14+1),0),IF(J$6<=Teams!$H14,Teams!$E14,ROUND(Teams!$E14*(Teams!$I14-J$6+1)/(Teams!$I14-Teams!$H14),0)))) | ... AN16: =IF(OR(AN$6<Teams!$F14,AN$6>Teams!$I14),0,IF(AN$6<Teams!$G14,ROUND(Teams!$E14*(AN$6-Teams!$F14+1)/(Teams!$G14-Teams!$F14+1),0),IF(AN$6<=Teams!$H14,Teams!$E14,ROUND(Teams!$E14*(Teams!$I14-AN$6+1)/(Teams!$I14-Teams!$H14),0))))
A17: =Teams!A15 | B17: =Teams!C15&" — "&Teams!B15 | C17: =IF(OR(C$6<Teams!$F15,C$6>Teams!$I15),0,IF(C$6<Teams!$G15,ROUND(Teams!$E15*(C$6-Teams!$F15+1)/(Teams!$G15-Teams!$F15+1),0),IF(C$6<=Teams!$H15,Teams!$E15,ROUND(Teams!$E15*(Teams!$I15-C$6+1)/(Teams!$I15-Teams!$H15),0)))) | D17: =IF(OR(D$6<Teams!$F15,D$6>Teams!$I15),0,IF(D$6<Teams!$G15,ROUND(Teams!$E15*(D$6-Teams!$F15+1)/(Teams!$G15-Teams!$F15+1),0),IF(D$6<=Teams!$H15,Teams!$E15,ROUND(Teams!$E15*(Teams!$I15-D$6+1)/(Teams!$I15-Teams!$H15),0)))) | E17: =IF(OR(E$6<Teams!$F15,E$6>Teams!$I15),0,IF(E$6<Teams!$G15,ROUND(Teams!$E15*(E$6-Teams!$F15+1)/(Teams!$G15-Teams!$F15+1),0),IF(E$6<=Teams!$H15,Teams!$E15,ROUND(Teams!$E15*(Teams!$I15-E$6+1)/(Teams!$I15-Teams!$H15),0)))) | F17: =IF(OR(F$6<Teams!$F15,F$6>Teams!$I15),0,IF(F$6<Teams!$G15,ROUND(Teams!$E15*(F$6-Teams!$F15+1)/(Teams!$G15-Teams!$F15+1),0),IF(F$6<=Teams!$H15,Teams!$E15,ROUND(Teams!$E15*(Teams!$I15-F$6+1)/(Teams!$I15-Teams!$H15),0)))) | G17: =IF(OR(G$6<Teams!$F15,G$6>Teams!$I15),0,IF(G$6<Teams!$G15,ROUND(Teams!$E15*(G$6-Teams!$F15+1)/(Teams!$G15-Teams!$F15+1),0),IF(G$6<=Teams!$H15,Teams!$E15,ROUND(Teams!$E15*(Teams!$I15-G$6+1)/(Teams!$I15-Teams!$H15),0)))) | H17: =IF(OR(H$6<Teams!$F15,H$6>Teams!$I15),0,IF(H$6<Teams!$G15,ROUND(Teams!$E15*(H$6-Teams!$F15+1)/(Teams!$G15-Teams!$F15+1),0),IF(H$6<=Teams!$H15,Teams!$E15,ROUND(Teams!$E15*(Teams!$I15-H$6+1)/(Teams!$I15-Teams!$H15),0)))) | I17: =IF(OR(I$6<Teams!$F15,I$6>Teams!$I15),0,IF(I$6<Teams!$G15,ROUND(Teams!$E15*(I$6-Teams!$F15+1)/(Teams!$G15-Teams!$F15+1),0),IF(I$6<=Teams!$H15,Teams!$E15,ROUND(Teams!$E15*(Teams!$I15-I$6+1)/(Teams!$I15-Teams!$H15),0)))) | J17: =IF(OR(J$6<Teams!$F15,J$6>Teams!$I15),0,IF(J$6<Teams!$G15,ROUND(Teams!$E15*(J$6-Teams!$F15+1)/(Teams!$G15-Teams!$F15+1),0),IF(J$6<=Teams!$H15,Teams!$E15,ROUND(Teams!$E15*(Teams!$I15-J$6+1)/(Teams!$I15-Teams!$H15),0)))) | ... AN17: =IF(OR(AN$6<Teams!$F15,AN$6>Teams!$I15),0,IF(AN$6<Teams!$G15,ROUND(Teams!$E15*(AN$6-Teams!$F15+1)/(Teams!$G15-Teams!$F15+1),0),IF(AN$6<=Teams!$H15,Teams!$E15,ROUND(Teams!$E15*(Teams!$I15-AN$6+1)/(Teams!$I15-Teams!$H15),0))))
A18: =Teams!A16 | B18: =Teams!C16&" — "&Teams!B16 | C18: =IF(OR(C$6<Teams!$F16,C$6>Teams!$I16),0,IF(C$6<Teams!$G16,ROUND(Teams!$E16*(C$6-Teams!$F16+1)/(Teams!$G16-Teams!$F16+1),0),IF(C$6<=Teams!$H16,Teams!$E16,ROUND(Teams!$E16*(Teams!$I16-C$6+1)/(Teams!$I16-Teams!$H16),0)))) | D18: =IF(OR(D$6<Teams!$F16,D$6>Teams!$I16),0,IF(D$6<Teams!$G16,ROUND(Teams!$E16*(D$6-Teams!$F16+1)/(Teams!$G16-Teams!$F16+1),0),IF(D$6<=Teams!$H16,Teams!$E16,ROUND(Teams!$E16*(Teams!$I16-D$6+1)/(Teams!$I16-Teams!$H16),0)))) | E18: =IF(OR(E$6<Teams!$F16,E$6>Teams!$I16),0,IF(E$6<Teams!$G16,ROUND(Teams!$E16*(E$6-Teams!$F16+1)/(Teams!$G16-Teams!$F16+1),0),IF(E$6<=Teams!$H16,Teams!$E16,ROUND(Teams!$E16*(Teams!$I16-E$6+1)/(Teams!$I16-Teams!$H16),0)))) | F18: =IF(OR(F$6<Teams!$F16,F$6>Teams!$I16),0,IF(F$6<Teams!$G16,ROUND(Teams!$E16*(F$6-Teams!$F16+1)/(Teams!$G16-Teams!$F16+1),0),IF(F$6<=Teams!$H16,Teams!$E16,ROUND(Teams!$E16*(Teams!$I16-F$6+1)/(Teams!$I16-Teams!$H16),0)))) | G18: =IF(OR(G$6<Teams!$F16,G$6>Teams!$I16),0,IF(G$6<Teams!$G16,ROUND(Teams!$E16*(G$6-Teams!$F16+1)/(Teams!$G16-Teams!$F16+1),0),IF(G$6<=Teams!$H16,Teams!$E16,ROUND(Teams!$E16*(Teams!$I16-G$6+1)/(Teams!$I16-Teams!$H16),0)))) | H18: =IF(OR(H$6<Teams!$F16,H$6>Teams!$I16),0,IF(H$6<Teams!$G16,ROUND(Teams!$E16*(H$6-Teams!$F16+1)/(Teams!$G16-Teams!$F16+1),0),IF(H$6<=Teams!$H16,Teams!$E16,ROUND(Teams!$E16*(Teams!$I16-H$6+1)/(Teams!$I16-Teams!$H16),0)))) | I18: =IF(OR(I$6<Teams!$F16,I$6>Teams!$I16),0,IF(I$6<Teams!$G16,ROUND(Teams!$E16*(I$6-Teams!$F16+1)/(Teams!$G16-Teams!$F16+1),0),IF(I$6<=Teams!$H16,Teams!$E16,ROUND(Teams!$E16*(Teams!$I16-I$6+1)/(Teams!$I16-Teams!$H16),0)))) | J18: =IF(OR(J$6<Teams!$F16,J$6>Teams!$I16),0,IF(J$6<Teams!$G16,ROUND(Teams!$E16*(J$6-Teams!$F16+1)/(Teams!$G16-Teams!$F16+1),0),IF(J$6<=Teams!$H16,Teams!$E16,ROUND(Teams!$E16*(Teams!$I16-J$6+1)/(Teams!$I16-Teams!$H16),0)))) | ... AN18: =IF(OR(AN$6<Teams!$F16,AN$6>Teams!$I16),0,IF(AN$6<Teams!$G16,ROUND(Teams!$E16*(AN$6-Teams!$F16+1)/(Teams!$G16-Teams!$F16+1),0),IF(AN$6<=Teams!$H16,Teams!$E16,ROUND(Teams!$E16*(Teams!$I16-AN$6+1)/(Teams!$I16-Teams!$H16),0))))
... A28: =Teams!A26 | B28: =Teams!C26&" — "&Teams!B26 | C28: =IF(OR(C$6<Teams!$F26,C$6>Teams!$I26),0,IF(C$6<Teams!$G26,ROUND(Teams!$E26*(C$6-Teams!$F26+1)/(Teams!$G26-Teams!$F26+1),0),IF(C$6<=Teams!$H26,Teams!$E26,ROUND(Teams!$E26*(Teams!$I26-C$6+1)/(Teams!$I26-Teams!$H26),0)))) | D28: =IF(OR(D$6<Teams!$F26,D$6>Teams!$I26),0,IF(D$6<Teams!$G26,ROUND(Teams!$E26*(D$6-Teams!$F26+1)/(Teams!$G26-Teams!$F26+1),0),IF(D$6<=Teams!$H26,Teams!$E26,ROUND(Teams!$E26*(Teams!$I26-D$6+1)/(Teams!$I26-Teams!$H26),0)))) | E28: =IF(OR(E$6<Teams!$F26,E$6>Teams!$I26),0,IF(E$6<Teams!$G26,ROUND(Teams!$E26*(E$6-Teams!$F26+1)/(Teams!$G26-Teams!$F26+1),0),IF(E$6<=Teams!$H26,Teams!$E26,ROUND(Teams!$E26*(Teams!$I26-E$6+1)/(Teams!$I26-Teams!$H26),0)))) | F28: =IF(OR(F$6<Teams!$F26,F$6>Teams!$I26),0,IF(F$6<Teams!$G26,ROUND(Teams!$E26*(F$6-Teams!$F26+1)/(Teams!$G26-Teams!$F26+1),0),IF(F$6<=Teams!$H26,Teams!$E26,ROUND(Teams!$E26*(Teams!$I26-F$6+1)/(Teams!$I26-Teams!$H26),0)))) | G28: =IF(OR(G$6<Teams!$F26,G$6>Teams!$I26),0,IF(G$6<Teams!$G26,ROUND(Teams!$E26*(G$6-Teams!$F26+1)/(Teams!$G26-Teams!$F26+1),0),IF(G$6<=Teams!$H26,Teams!$E26,ROUND(Teams!$E26*(Teams!$I26-G$6+1)/(Teams!$I26-Teams!$H26),0)))) | H28: =IF(OR(H$6<Teams!$F26,H$6>Teams!$I26),0,IF(H$6<Teams!$G26,ROUND(Teams!$E26*(H$6-Teams!$F26+1)/(Teams!$G26-Teams!$F26+1),0),IF(H$6<=Teams!$H26,Teams!$E26,ROUND(Teams!$E26*(Teams!$I26-H$6+1)/(Teams!$I26-Teams!$H26),0)))) | I28: =IF(OR(I$6<Teams!$F26,I$6>Teams!$I26),0,IF(I$6<Teams!$G26,ROUND(Teams!$E26*(I$6-Teams!$F26+1)/(Teams!$G26-Teams!$F26+1),0),IF(I$6<=Teams!$H26,Teams!$E26,ROUND(Teams!$E26*(Teams!$I26-I$6+1)/(Teams!$I26-Teams!$H26),0)))) | J28: =IF(OR(J$6<Teams!$F26,J$6>Teams!$I26),0,IF(J$6<Teams!$G26,ROUND(Teams!$E26*(J$6-Teams!$F26+1)/(Teams!$G26-Teams!$F26+1),0),IF(J$6<=Teams!$H26,Teams!$E26,ROUND(Teams!$E26*(Teams!$I26-J$6+1)/(Teams!$I26-Teams!$H26),0)))) | ... AN28: =IF(OR(AN$6<Teams!$F26,AN$6>Teams!$I26),0,IF(AN$6<Teams!$G26,ROUND(Teams!$E26*(AN$6-Teams!$F26+1)/(Teams!$G26-Teams!$F26+1),0),IF(AN$6<=Teams!$H26,Teams!$E26,ROUND(Teams!$E26*(Teams!$I26-AN$6+1)/(Teams!$I26-Teams!$H26),0))))
B29: TOTAL SITE POPULATION | C29: =SUM(C7:C28) | D29: =SUM(D7:D28) | E29: =SUM(E7:E28) | F29: =SUM(F7:F28) | G29: =SUM(G7:G28) | H29: =SUM(H7:H28) | I29: =SUM(I7:I28) | J29: =SUM(J7:J28) | ... AN29: =SUM(AN7:AN28)
B31: Peak site population | C31: =MAX(C29:AN29)
B32: Month of peak | C32: =MATCH(C31,C29:AN29,0)
B33: Average over the programme | C33: =ROUND(AVERAGE(C29:AN29),0)
B34: Person-months of exposure | C34: =SUM(C29:AN29)

Sheet BedDemand
A2: BED DEMAND — WHO NEEDS A ROOM, MONTH BY MONTH
A3: The whole village follows from this sheet. Headcount from Workforce, travelling percentage from Teams, everything else from Assumptions.
B5: Month | C5: =Workforce!C5 | D5: =Workforce!D5 | E5: =Workforce!E5 | F5: =Workforce!F5 | G5: =Workforce!G5 | H5: =Workforce!H5 | I5: =Workforce!I5 | J5: =Workforce!J5 | ... AN5: =Workforce!AN5
B6: Month number | C6: 1 | D6: 2 | E6: 3 | F6: 4 | G6: 5 | H6: 6 | I6: 7 | J6: 8 | K6: 9 | L6: 10 | M6: 11 | N6: 12 | O6: 13 | P6: 14 | Q6: 15 | R6: 16 | S6: 17 | T6: 18 | U6: 19 | V6: 20 | W6: 21 | X6: 22 | Y6: 23 | Z6: 24 | AA6: 25 | AB6: 26 | AC6: 27 | AD6: 28 | AE6: 29 | AF6: 30 | AG6: 31 | AH6: 32 | AI6: 33 | AJ6: 34 | AK6: 35 | AL6: 36 | AM6: 37 | AN6: 38
B7: Travelling workers (need accommodation) | C7: =ROUND(SUMPRODUCT(Workforce!C$7:C$28,Teams!$J$5:$J$26),0) | D7: =ROUND(SUMPRODUCT(Workforce!D$7:D$28,Teams!$J$5:$J$26),0) | E7: =ROUND(SUMPRODUCT(Workforce!E$7:E$28,Teams!$J$5:$J$26),0) | F7: =ROUND(SUMPRODUCT(Workforce!F$7:F$28,Teams!$J$5:$J$26),0) | G7: =ROUND(SUMPRODUCT(Workforce!G$7:G$28,Teams!$J$5:$J$26),0) | H7: =ROUND(SUMPRODUCT(Workforce!H$7:H$28,Teams!$J$5:$J$26),0) | I7: =ROUND(SUMPRODUCT(Workforce!I$7:I$28,Teams!$J$5:$J$26),0) | J7: =ROUND(SUMPRODUCT(Workforce!J$7:J$28,Teams!$J$5:$J$26),0) | ... AN7: =ROUND(SUMPRODUCT(Workforce!AN$7:AN$28,Teams!$J$5:$J$26),0) | AP7: Headcount × each team's travelling percentage. A local team of 30 needs no beds; a commissioning team of 18 needs 17.
B8: Local / commuting workers | C8: =Workforce!C$29-C7 | D8: =Workforce!D$29-D7 | E8: =Workforce!E$29-E7 | F8: =Workforce!F$29-F7 | G8: =Workforce!G$29-G7 | H8: =Workforce!H$29-H7 | I8: =Workforce!I$29-I7 | J8: =Workforce!J$29-J7 | ... AN8: =Workforce!AN$29-AN7 | AP8: Go home at night. They still eat, park and use welfare on site.
B9: Present at any one time (rotation applied) | C9: =C7*Assumptions!$C$17 | D9: =D7*Assumptions!$C$17 | E9: =E7*Assumptions!$C$17 | F9: =F7*Assumptions!$C$17 | G9: =G7*Assumptions!$C$17 | H9: =H7*Assumptions!$C$17 | I9: =I7*Assumptions!$C$17 | J9: =J7*Assumptions!$C$17 | ... AN9: =AN7*Assumptions!$C$17 | AP9: A rotation means not everyone is on site at once. At 1.00 this line equals the one above.
B10: Rooms required for residents | C10: =ROUNDUP(C9*Assumptions!$C$16,0) | D10: =ROUNDUP(D9*Assumptions!$C$16,0) | E10: =ROUNDUP(E9*Assumptions!$C$16,0) | F10: =ROUNDUP(F9*Assumptions!$C$16,0) | G10: =ROUNDUP(G9*Assumptions!$C$16,0) | H10: =ROUNDUP(H9*Assumptions!$C$16,0) | I10: =ROUNDUP(I9*Assumptions!$C$16,0) | J10: =ROUNDUP(J9*Assumptions!$C$16,0) | ... AN10: =ROUNDUP(AN9*Assumptions!$C$16,0)
B11: Void and turnover allowance | C11: =ROUNDUP(C10*Assumptions!$C$18,0) | D11: =ROUNDUP(D10*Assumptions!$C$18,0) | E11: =ROUNDUP(E10*Assumptions!$C$18,0) | F11: =ROUNDUP(F10*Assumptions!$C$18,0) | G11: =ROUNDUP(G10*Assumptions!$C$18,0) | H11: =ROUNDUP(H10*Assumptions!$C$18,0) | I11: =ROUNDUP(I10*Assumptions!$C$18,0) | J11: =ROUNDUP(J10*Assumptions!$C$18,0) | ... AN11: =ROUNDUP(AN10*Assumptions!$C$18,0) | AP11: Rooms unavailable for cleaning, changeover, damage or maintenance.
B12: Contingency | C12: =ROUNDUP(C10*Assumptions!$C$19,0) | D12: =ROUNDUP(D10*Assumptions!$C$19,0) | E12: =ROUNDUP(E10*Assumptions!$C$19,0) | F12: =ROUNDUP(F10*Assumptions!$C$19,0) | G12: =ROUNDUP(G10*Assumptions!$C$19,0) | H12: =ROUNDUP(H10*Assumptions!$C$19,0) | I12: =ROUNDUP(I10*Assumptions!$C$19,0) | J12: =ROUNDUP(J10*Assumptions!$C$19,0) | ... AN12: =ROUNDUP(AN10*Assumptions!$C$19,0)
B13: Visitor and spare rooms | C13: =IF(C10>0,Assumptions!$C$23,0) | D13: =IF(D10>0,Assumptions!$C$23,0) | E13: =IF(E10>0,Assumptions!$C$23,0) | F13: =IF(F10>0,Assumptions!$C$23,0) | G13: =IF(G10>0,Assumptions!$C$23,0) | H13: =IF(H10>0,Assumptions!$C$23,0) | I13: =IF(I10>0,Assumptions!$C$23,0) | J13: =IF(J10>0,Assumptions!$C$23,0) | ... AN13: =IF(AN10>0,Assumptions!$C$23,0)
B14: TOTAL ROOMS REQUIRED | C14: =SUM(C10:C13) | D14: =SUM(D10:D13) | E14: =SUM(E10:E13) | F14: =SUM(F10:F13) | G14: =SUM(G10:G13) | H14: =SUM(H10:H13) | I14: =SUM(I10:I13) | J14: =SUM(J10:J13) | ... AN14: =SUM(AN10:AN13) | AP14: This curve is what the village must satisfy. The peak sizes it; the shape decides whether you phase it.
B15: Helper — month number where rooms are needed | C15: =IF(C14>0,C$6,"") | D15: =IF(D14>0,D$6,"") | E15: =IF(E14>0,E$6,"") | F15: =IF(F14>0,F$6,"") | G15: =IF(G14>0,G$6,"") | H15: =IF(H14>0,H$6,"") | I15: =IF(I14>0,I$6,"") | J15: =IF(J14>0,J$6,"") | ... AN15: =IF(AN14>0,AN$6,"")
B16: Occupancy rate against the built village | C16: =IF($C$22=0,0,C10/$C$22) | D16: =IF($C$22=0,0,D10/$C$22) | E16: =IF($C$22=0,0,E10/$C$22) | F16: =IF($C$22=0,0,F10/$C$22) | G16: =IF($C$22=0,0,G10/$C$22) | H16: =IF($C$22=0,0,H10/$C$22) | I16: =IF($C$22=0,0,I10/$C$22) | J16: =IF($C$22=0,0,J10/$C$22) | ... AN16: =IF($C$22=0,0,AN10/$C$22) | AP16: Against the peak-sized village. The low months are the cost of building for the peak.
B18: THE NUMBERS THAT SIZE THE VILLAGE
B20: Peak rooms required | C20: =MAX(C14:AN14) | E20: The village is built to this.
B21: Month of peak | C21: =MATCH(C20,C14:AN14,0) | E21: Everything upstream must be finished before it.
B22: Peak resident rooms (excluding void, contingency, visitors) | C22: =MAX(C10:AN10)
B23: First month with any bed demand | C23: =MIN(C15:AN15) | E23: The village must be live before this month, not in it.
B24: Last month with bed demand | C24: =MAX(C15:AN15)
B25: Bed-nights over the programme | C25: =ROUND(SUM(C10:AN10)*30.4,0) | E25: Drives catering, utilities and the unit cost of the whole thing.
B26: Average occupancy across the live period | C26: =IFERROR(AVERAGEIF(C10:AN10,">0")/$C$22,0) | E26: Below about 70% the case for phasing the village gets strong.
B28: BEDS BY COMPANY — WHO IS RECHARGED FOR WHAT
B29: Company | C29: Peak beds | D29: Bed-months | E29: Share of bed-months | AP29: Helper — resident rooms by company by month (hide these columns)
B30: Ashfell M&E Ltd | C30: =MAX(AP30:CA30) | D30: =ROUND(SUM(AP30:CA30),0) | E30: =IFERROR(D30/SUM($D$30:$D$43),0) | AP30: =SUMPRODUCT((Teams!$B$5:$B$26=$B30)*Workforce!C$7:C$28*Teams!$J$5:$J$26)*Assumptions!$C$17*Assumptions!$C$16 | AQ30: =SUMPRODUCT((Teams!$B$5:$B$26=$B30)*Workforce!D$7:D$28*Teams!$J$5:$J$26)*Assumptions!$C$17*Assumptions!$C$16 | AR30: =SUMPRODUCT((Teams!$B$5:$B$26=$B30)*Workforce!E$7:E$28*Teams!$J$5:$J$26)*Assumptions!$C$17*Assumptions!$C$16 | AS30: =SUMPRODUCT((Teams!$B$5:$B$26=$B30)*Workforce!F$7:F$28*Teams!$J$5:$J$26)*Assumptions!$C$17*Assumptions!$C$16 | AT30: =SUMPRODUCT((Teams!$B$5:$B$26=$B30)*Workforce!G$7:G$28*Teams!$J$5:$J$26)*Assumptions!$C$17*Assumptions!$C$16 | AU30: =SUMPRODUCT((Teams!$B$5:$B$26=$B30)*Workforce!H$7:H$28*Teams!$J$5:$J$26)*Assumptions!$C$17*Assumptions!$C$16 | AV30: =SUMPRODUCT((Teams!$B$5:$B$26=$B30)*Workforce!I$7:I$28*Teams!$J$5:$J$26)*Assumptions!$C$17*Assumptions!$C$16 | AW30: =SUMPRODUCT((Teams!$B$5:$B$26=$B30)*Workforce!J$7:J$28*Teams!$J$5:$J$26)*Assumptions!$C$17*Assumptions!$C$16 | ... CA30: =SUMPRODUCT((Teams!$B$5:$B$26=$B30)*Workforce!AN$7:AN$28*Teams!$J$5:$J$26)*Assumptions!$C$17*Assumptions!$C$16
B31: Brightbay Facilities Management Ltd | C31: =MAX(AP31:CA31) | D31: =ROUND(SUM(AP31:CA31),0) | E31: =IFERROR(D31/SUM($D$30:$D$43),0) | AP31: =SUMPRODUCT((Teams!$B$5:$B$26=$B31)*Workforce!C$7:C$28*Teams!$J$5:$J$26)*Assumptions!$C$17*Assumptions!$C$16 | AQ31: =SUMPRODUCT((Teams!$B$5:$B$26=$B31)*Workforce!D$7:D$28*Teams!$J$5:$J$26)*Assumptions!$C$17*Assumptions!$C$16 | AR31: =SUMPRODUCT((Teams!$B$5:$B$26=$B31)*Workforce!E$7:E$28*Teams!$J$5:$J$26)*Assumptions!$C$17*Assumptions!$C$16 | AS31: =SUMPRODUCT((Teams!$B$5:$B$26=$B31)*Workforce!F$7:F$28*Teams!$J$5:$J$26)*Assumptions!$C$17*Assumptions!$C$16 | AT31: =SUMPRODUCT((Teams!$B$5:$B$26=$B31)*Workforce!G$7:G$28*Teams!$J$5:$J$26)*Assumptions!$C$17*Assumptions!$C$16 | AU31: =SUMPRODUCT((Teams!$B$5:$B$26=$B31)*Workforce!H$7:H$28*Teams!$J$5:$J$26)*Assumptions!$C$17*Assumptions!$C$16 | AV31: =SUMPRODUCT((Teams!$B$5:$B$26=$B31)*Workforce!I$7:I$28*Teams!$J$5:$J$26)*Assumptions!$C$17*Assumptions!$C$16 | AW31: =SUMPRODUCT((Teams!$B$5:$B$26=$B31)*Workforce!J$7:J$28*Teams!$J$5:$J$26)*Assumptions!$C$17*Assumptions!$C$16 | ... CA31: =SUMPRODUCT((Teams!$B$5:$B$26=$B31)*Workforce!AN$7:AN$28*Teams!$J$5:$J$26)*Assumptions!$C$17*Assumptions!$C$16
B32: Calderbrook Civils Ltd | C32: =MAX(AP32:CA32) | D32: =ROUND(SUM(AP32:CA32),0) | E32: =IFERROR(D32/SUM($D$30:$D$43),0) | AP32: =SUMPRODUCT((Teams!$B$5:$B$26=$B32)*Workforce!C$7:C$28*Teams!$J$5:$J$26)*Assumptions!$C$17*Assumptions!$C$16 | AQ32: =SUMPRODUCT((Teams!$B$5:$B$26=$B32)*Workforce!D$7:D$28*Teams!$J$5:$J$26)*Assumptions!$C$17*Assumptions!$C$16 | AR32: =SUMPRODUCT((Teams!$B$5:$B$26=$B32)*Workforce!E$7:E$28*Teams!$J$5:$J$26)*Assumptions!$C$17*Assumptions!$C$16 | AS32: =SUMPRODUCT((Teams!$B$5:$B$26=$B32)*Workforce!F$7:F$28*Teams!$J$5:$J$26)*Assumptions!$C$17*Assumptions!$C$16 | AT32: =SUMPRODUCT((Teams!$B$5:$B$26=$B32)*Workforce!G$7:G$28*Teams!$J$5:$J$26)*Assumptions!$C$17*Assumptions!$C$16 | AU32: =SUMPRODUCT((Teams!$B$5:$B$26=$B32)*Workforce!H$7:H$28*Teams!$J$5:$J$26)*Assumptions!$C$17*Assumptions!$C$16 | AV32: =SUMPRODUCT((Teams!$B$5:$B$26=$B32)*Workforce!I$7:I$28*Teams!$J$5:$J$26)*Assumptions!$C$17*Assumptions!$C$16 | AW32: =SUMPRODUCT((Teams!$B$5:$B$26=$B32)*Workforce!J$7:J$28*Teams!$J$5:$J$26)*Assumptions!$C$17*Assumptions!$C$16 | ... CA32: =SUMPRODUCT((Teams!$B$5:$B$26=$B32)*Workforce!AN$7:AN$28*Teams!$J$5:$J$26)*Assumptions!$C$17*Assumptions!$C$16
B33: Hollins Catering Ltd | C33: =MAX(AP33:CA33) | D33: =ROUND(SUM(AP33:CA33),0) | E33: =IFERROR(D33/SUM($D$30:$D$43),0) | AP33: =SUMPRODUCT((Teams!$B$5:$B$26=$B33)*Workforce!C$7:C$28*Teams!$J$5:$J$26)*Assumptions!$C$17*Assumptions!$C$16 | AQ33: =SUMPRODUCT((Teams!$B$5:$B$26=$B33)*Workforce!D$7:D$28*Teams!$J$5:$J$26)*Assumptions!$C$17*Assumptions!$C$16 | AR33: =SUMPRODUCT((Teams!$B$5:$B$26=$B33)*Workforce!E$7:E$28*Teams!$J$5:$J$26)*Assumptions!$C$17*Assumptions!$C$16 | AS33: =SUMPRODUCT((Teams!$B$5:$B$26=$B33)*Workforce!F$7:F$28*Teams!$J$5:$J$26)*Assumptions!$C$17*Assumptions!$C$16 | AT33: =SUMPRODUCT((Teams!$B$5:$B$26=$B33)*Workforce!G$7:G$28*Teams!$J$5:$J$26)*Assumptions!$C$17*Assumptions!$C$16 | AU33: =SUMPRODUCT((Teams!$B$5:$B$26=$B33)*Workforce!H$7:H$28*Teams!$J$5:$J$26)*Assumptions!$C$17*Assumptions!$C$16 | AV33: =SUMPRODUCT((Teams!$B$5:$B$26=$B33)*Workforce!I$7:I$28*Teams!$J$5:$J$26)*Assumptions!$C$17*Assumptions!$C$16 | AW33: =SUMPRODUCT((Teams!$B$5:$B$26=$B33)*Workforce!J$7:J$28*Teams!$J$5:$J$26)*Assumptions!$C$17*Assumptions!$C$16 | ... CA33: =SUMPRODUCT((Teams!$B$5:$B$26=$B33)*Workforce!AN$7:AN$28*Teams!$J$5:$J$26)*Assumptions!$C$17*Assumptions!$C$16
B34: Ironvale Welding Ltd | C34: =MAX(AP34:CA34) | D34: =ROUND(SUM(AP34:CA34),0) | E34: =IFERROR(D34/SUM($D$30:$D$43),0) | AP34: =SUMPRODUCT((Teams!$B$5:$B$26=$B34)*Workforce!C$7:C$28*Teams!$J$5:$J$26)*Assumptions!$C$17*Assumptions!$C$16 | AQ34: =SUMPRODUCT((Teams!$B$5:$B$26=$B34)*Workforce!D$7:D$28*Teams!$J$5:$J$26)*Assumptions!$C$17*Assumptions!$C$16 | AR34: =SUMPRODUCT((Teams!$B$5:$B$26=$B34)*Workforce!E$7:E$28*Teams!$J$5:$J$26)*Assumptions!$C$17*Assumptions!$C$16 | AS34: =SUMPRODUCT((Teams!$B$5:$B$26=$B34)*Workforce!F$7:F$28*Teams!$J$5:$J$26)*Assumptions!$C$17*Assumptions!$C$16 | AT34: =SUMPRODUCT((Teams!$B$5:$B$26=$B34)*Workforce!G$7:G$28*Teams!$J$5:$J$26)*Assumptions!$C$17*Assumptions!$C$16 | AU34: =SUMPRODUCT((Teams!$B$5:$B$26=$B34)*Workforce!H$7:H$28*Teams!$J$5:$J$26)*Assumptions!$C$17*Assumptions!$C$16 | AV34: =SUMPRODUCT((Teams!$B$5:$B$26=$B34)*Workforce!I$7:I$28*Teams!$J$5:$J$26)*Assumptions!$C$17*Assumptions!$C$16 | AW34: =SUMPRODUCT((Teams!$B$5:$B$26=$B34)*Workforce!J$7:J$28*Teams!$J$5:$J$26)*Assumptions!$C$17*Assumptions!$C$16 | ... CA34: =SUMPRODUCT((Teams!$B$5:$B$26=$B34)*Workforce!AN$7:AN$28*Teams!$J$5:$J$26)*Assumptions!$C$17*Assumptions!$C$16
